tests/64_threads/sample_69.in
64
o
63 S 102 1 155 477
58 B 103 7 164 467
59 B 104 6 186 46
59 C 104
12 B 107 3 175 137
48 B 108 7 116 997
53 S 110 5 103 744
33 B 111 2 181 293
53 S 112 2 174 599
50 B 113 1 124 405
5 S 115 6 188 803
18 B 116 5 180 954
43 B 117 9 103 326
19 S 118 5 151 781
22 S 119 9 189 711
49 S 120 5 145 566
15 B 121 0 163 762
34 S 122 5 102 747
27 B 123 9 153 240
11 B 124 3 140 747
62 S 127 3 169 775
3 B 129 7 147 169
46 S 133 3 169 654
12 C 107
44 B 136 3 158 586
22 B 137 8 158 748
16 B 138 5 186 930
38 S 139 3 140 280
5 S 140 5 194 956
39 B 141 7 139 825
27 S 142 6 181 868
45 S 144 9 136 85
53 S 145 8 125 420
58 S 146 8 100 221
26 B 148 8 170 146
16 B 150 8 161 357
12 B 151 5 158 47
5 S 153 0 156 630
24 B 154 9 175 493
57 B 155 9 135 124
39 S 157 2 151 984
25 S 158 8 151 411
16 C 150
54 B 160 3 115 321
59 C 104
60 B 163 1 147 946
27 S 164 0 191 976
50 S 165 8 103 838
38 C 139
11 S 167 2 131 844
18 C 116
50 S 169 6 146 997
48 B 170 2 106 110
16 S 171 6 198 22
3 B 172 6 132 739
50 B 174 2 187 74
25 S 175 9 172 800
33 C 111
6 B 177 0 184 744
1 S 178 7 160 857
48 C 170
18 C 116
12 C 151
51 B 184 5 105 598
14 B 185 0 181 989
53 S 186 5 146 223
19 B 187 2 137 326
53 S 188 3 171 505
41 S 189 8 114 70
33 S 190 4 145 891
30 S 192 4 119 48
5 C 140
55 S 194 2 126 523
14 B 196 0 137 589
58 C 103
34 S 198 9 186 317
60 S 199 9 133 573
18 C 116
50 B 201 8 147 960
24 C 154
27 C 164
41 C 189
18 B 206 5 163 923
38 C 139
48 C 108
1 B 211 2 113 394
28 B 212 6 183 772
5 C 140
52 S 214 2 135 642
21 S 215 0 114 24
15 B 216 7 164 478
26 C 148
53 C 186
62 S 219 6 152 782
59 C 104
11 S 221 4 170 891
62 C 219
23 S 224 5 172 792
46 S 225 0 190 674
27 C 123
14 B 227 4 112 438
22 C 137
35 S 229 5 131 538
41 C 189
62 B 231 8 110 611
9 B 232 3 137 602
30 S 233 3 143 453
16 C 138
30 S 235 8 188 555
57 B 236 2 172 605
27 S 237 3 131 163
24 C 154
15 B 239 1 170 48
23 B 240 9 142 965
10 B 241 8 120 500
31 S 242 7 185 235
53 B 243 3 188 828
5 S 244 1 132 908
14 B 245 6 183 336
27 S 246 1 148 456
19 S 247 2 151 413
41 C 189
38 S 249 2 102 589
15 B 250 3 200 161
46 B 251 9 162 973
49 S 252 4 160 760
8 S 253 1 160 760
4 S 254 5 107 423
50 C 113
18 B 257 0 178 280
38 C 249
26 S 259 0 167 460
60 S 260 5 134 481
21 B 261 6 155 143
45 S 262 4 161 750
9 C 232
6 B 264 1 147 41
62 S 265 8 132 221
36 B 266 5 166 195
6 C 177
30 S 268 6 176 105
8 S 269 1 155 164
27 S 270 7 194 583
21 S 271 9 134 111
7 B 273 9 138 19
57 S 274 3 139 915
30 B 275 6 200 764
51 B 276 4 176 441
33 S 277 1 145 601
30 B 278 5 180 634
46 S 279 9 170 116
62 C 231
45 C 262
58 S 284 1 172 522
22 S 285 7 193 470
22 B 286 7 173 481
15 S 287 3 191 614
40 B 288 6 157 939
34 C 122
19 C 187
39 C 157
44 B 293 6 159 707
30 B 294 3 194 886
31 B 295 9 133 289
26 C 148
32 B 297 8 149 946
28 S 298 3 185 259
14 B 299 1 154 821
16 S 300 8 103 13
54 S 301 3 113 596
24 C 154
8 B 303 1 156 637
3 C 172
34 S 305 2 153 269
15 S 306 4 182 873
25 C 175
31 C 242
12 S 309 3 148 59
11 B 310 8 169 153
58 C 284
59 S 313 4 191 205
31 S 314 5 103 639
15 S 315 1 153 640
5 S 316 6 183 694
42 B 317 1 196 611
49 C 252
7 S 319 0 166 809
27 B 320 4 186 655
11 C 310
4 B 322 7 196 159
31 B 323 2 167 336
56 S 324 8 107 109
7 B 325 9 118 973
51 S 326 0 123 314
22 S 327 4 122 103
26 S 328 1 137 404
15 B 329 7 112 181
2 B 330 8 148 217
43 B 331 0 177 836
55 B 332 7 172 490
28 C 212
4 C 254
34 B 335 8 106 761
3 C 129
51 C 184
43 B 338 9 109 504
37 B 339 3 151 680
41 C 189
25 C 158
53 S 342 7 196 521
54 S 343 2 123 681
27 S 344 9 125 130
26 S 345 4 157 79
11 C 124
41 S 348 9 126 692
38 C 249
22 S 350 8 177 617
38 B 351 9 164 925
60 C 163
5 C 316
54 S 354 7 154 495
14 C 227
36 C 266
12 C 151
58 S 358 5 154 517
21 B 359 8 100 387
58 C 358
37 C 339
22 S 363 3 136 363
42 C 317
56 B 365 5 155 418
57 S 366 4 129 730
55 B 367 7 161 690
1 S 368 6 181 573
46 S 369 4 168 899
26 B 371 2 171 681
55 B 372 4 173 296
59 C 313
1 B 374 4 190 670
45 B 375 3 104 511
9 S 376 7 112 19
24 B 377 1 159 302
55 C 372
29 S 379 5 184 394
20 B 380 7 199 379
4 C 322
2 S 382 7 189 544
41 S 383 0 117 874
8 S 384 6 116 626
8 B 385 3 102 266
35 C 229
15 B 387 6 124 545
53 C 145
44 B 389 9 173 393
43 B 390 9 115 258
19 B 391 5 144 901
44 C 293
8 S 393 2 187 184
34 C 198
62 B 395 3 113 898
59 C 313
39 C 157
37 S 398 0 166 674
18 C 206
29 S 400 7 103 60
19 B 401 1 119 231
38 C 139
9 S 403 3 123 432
9 B 404 3 184 418
2 B 405 9 178 314
44 S 406 5 188 287
16 C 150
44 B 408 3 139 877
22 S 409 5 152 46
51 C 276
5 S 411 9 181 641
11 B 412 7 149 233
27 S 413 6 192 483
61 S 414 0 144 674
21 S 415 7 141 37
5 S 416 0 106 116
19 S 417 5 183 843
38 B 418 4 159 414
16 B 419 9 150 690
46 S 420 4 101 385
42 B 421 7 133 891
14 S 422 8 106 865
29 S 423 9 187 231
1 C 368
54 C 354
52 C 214
4 C 254
18 B 428 2 134 934
22 S 430 3 116 734
2 C 405
49 C 120
7 B 433 8 159 532
36 S 434 3 120 462
62 C 127
48 B 436 5 196 827
52 S 437 6 116 443
46 C 369
11 B 439 8 133 340
3 S 440 0 156 181
37 B 441 7 200 818
38 B 442 0 112 32
13 S 443 0 111 738
53 B 444 7 101 771
7 S 445 7 177 496
46 S 446 1 102 94
17 S 447 8 189 770
5 C 153
36 B 449 2 197 347
11 S 450 9 181 915
59 B 451 5 142 14
40 C 288
23 C 224
48 B 454 0 105 201
34 B 455 4 167 62
56 S 456 7 187 524
32 B 457 7 193 720
35 S 458 9 198 129
37 S 459 6 184 809
11 C 450
4 B 462 1 176 786
37 B 463 0 147 428
48 S 464 9 189 988
17 S 465 9 170 522
48 C 436
50 B 467 8 194 396
48 B 468 3 110 82
48 S 469 2 171 155
12 S 470 1 135 95
5 C 115
51 C 276
44 B 473 0 182 741
29 C 400
16 B 475 4 151 492
31 C 314
17 S 477 7 124 15
34 C 455
57 B 479 6 167 151
54 S 480 5 197 651
32 C 457
33 B 482 7 154 382
31 C 295
55 B 484 7 159 693
38 B 485 6 185 208
7 C 273
61 C 414
38 S 488 6 173 812
52 C 214
17 S 490 5 176 786
62 C 219
62 C 219
11 B 494 5 118 857
35 B 495 4 176 888
5 B 496 0 193 766
16 C 419
19 B 498 4 103 617
15 S 499 4 119 719
2 S 500 2 126 560
63 B 501 7 106 60
43 S 502 2 182 92
16 C 150
23 B 504 6 138 388
28 B 505 8 136 531
37 S 506 8 141 689
5 B 507 2 155 501
8 B 508 6 154 113
9 S 509 1 153 827
32 S 510 9 109 187
43 S 511 0 129 14
8 B 512 9 172 155
60 S 513 0 177 115
58 B 514 5 118 216
29 C 379
33 B 516 6 112 23
15 C 329
1 C 368
49 S 519 1 106 759
43 S 520 2 109 324
25 S 521 7 138 823
50 B 522 4 168 747
25 S 523 9 145 661
15 S 524 7 174 730
50 C 169
31 S 526 9 133 411
1 B 527 9 164 279
30 S 528 9 160 803
20 B 529 6 100 409
18 B 530 4 171 52
38 B 531 9 167 477
15 C 315
10 B 533 7 187 88
9 S 534 3 155 422
45 S 535 3 118 308
56 C 365
51 C 184
56 S 538 1 136 761
28 B 539 3 131 772
10 B 540 7 118 568
13 C 443
14 B 542 3 117 838
25 C 158
50 B 544 7 169 628
60 B 545 1 158 918
7 B 546 0 111 573
3 S 547 4 176 819
39 C 157
49 C 252
20 B 550 8 146 396
46 C 225
38 S 552 0 188 133
56 B 553 9 148 777
22 C 327
52 B 555 1 197 136
28 C 539
35 C 495
17 B 558 4 191 211
32 C 297
11 B 560 9 144 910
35 B 561 4 189 543
3 B 562 0 124 85
59 C 104
26 S 564 7 121 295
26 C 564
3 C 172
50 S 568 1 187 799
41 C 348
32 B 570 5 116 639
22 C 285
10 B 572 6 172 129
34 S 573 7 186 831
50 C 169
26 C 564
39 B 577 0 101 580
55 S 578 0 186 417
28 S 579 9 104 125
40 S 580 1 169 231
30 S 581 7 129 187
55 C 194
51 S 583 4 125 61
0 B 584 8 187 712
58 S 585 9 151 418
34 B 586 6 117 939
23 C 224
5 C 416
49 S 589 9 112 581
59 B 590 1 162 934
44 S 591 5 185 502
39 B 592 2 162 76
2 C 405
25 S 594 8 105 142
39 C 592
29 C 423
20 B 597 0 191 278
38 S 598 2 114 43
20 C 380
51 B 600 5 139 589
54 S 601 2 104 671
31 B 602 1 142 726
21 S 603 4 195 518
2 S 604 0 120 468
57 S 605 8 178 577
42 B 606 3 107 759
29 B 607 0 106 161
25 C 158
11 C 310
24 C 377
22 B 611 1 147 668
35 C 561
23 C 224
22 S 614 2 123 890
44 C 136
10 C 533
1 S 617 4 152 483
42 C 317
6 S 619 5 107 994
10 C 540
4 S 621 0 147 814
29 S 622 3 124 567
57 C 274
16 S 624 1 121 908
34 B 625 4 186 891
4 S 626 5 177 506
53 C 186
16 S 628 0 196 406
6 S 629 1 183 937
12 S 630 9 153 40
32 B 631 5 123 45
16 B 632 5 167 316
16 C 138
48 C 454
46 S 635 7 178 704
10 B 636 7 175 989
1 C 211
22 S 638 5 102 745
52 C 214
0 B 640 2 169 823
52 B 641 2 119 486
9 C 403
1 B 643 8 170 49
24 S 644 5 155 477
10 S 645 4 181 330
