tests/64_threads/sample_7.in
64
o
52 S 101 8 153 290
43 B 102 8 177 15
20 B 104 2 186 573
54 B 105 6 102 219
32 S 106 5 175 309
33 S 107 1 156 46
46 S 109 5 121 657
44 S 114 7 104 624
57 S 116 1 174 772
40 S 117 6 134 666
21 B 118 7 191 543
16 S 119 6 198 988
15 B 120 4 137 989
8 S 122 6 122 172
58 S 123 1 112 555
34 S 124 2 106 964
21 S 125 0 121 448
3 B 126 2 194 89
52 C 101
40 S 129 5 176 688
24 S 131 5 119 245
25 S 132 0 146 722
35 B 133 5 186 926
10 S 134 6 161 810
53 B 135 5 146 255
49 S 136 3 151 673
8 S 138 1 137 416
10 S 139 6 168 417
33 B 141 9 128 98
20 S 142 9 150 907
48 S 143 6 103 29
46 C 109
36 B 145 1 154 250
46 S 146 8 198 773
25 S 147 7 122 168
23 S 148 8 118 269
19 B 149 0 132 999
30 B 151 3 152 913
40 B 152 8 131 232
31 S 153 7 122 858
29 B 155 2 158 498
16 C 119
22 S 159 3 154 610
12 B 160 2 140 434
35 C 133
18 S 162 7 166 408
49 B 163 4 158 434
57 C 116
2 B 165 8 138 354
42 B 166 6 111 119
63 B 167 5 198 341
54 C 105
54 S 170 2 197 601
25 S 172 5 154 931
30 C 151
15 C 120
8 S 175 3 142 151
8 S 176 7 191 540
30 C 151
28 S 179 5 134 901
30 C 151
56 S 182 1 187 640
34 B 183 6 104 804
62 B 184 5 155 66
37 B 185 0 131 733
30 S 186 4 184 957
36 B 187 3 137 277
17 B 188 3 119 975
27 B 189 7 112 635
7 B 190 9 193 643
63 C 167
7 B 192 3 199 662
60 B 193 2 170 889
22 C 159
24 C 131
54 B 196 3 118 191
33 S 197 8 132 341
21 C 125
26 B 199 2 149 430
20 S 200 3 181 984
15 S 201 7 123 789
45 B 202 6 149 27
14 S 203 7 200 70
29 B 204 6 168 360
22 S 205 6 108 838
21 S 207 4 187 129
36 C 145
56 S 209 6 198 240
1 S 210 7 114 760
21 B 211 5 103 31
59 S 212 4 117 154
18 B 213 5 111 731
45 C 202
24 S 215 0 183 346
19 C 149
45 B 217 3 174 806
59 B 218 0 158 787
10 C 134
31 B 221 2 108 205
41 B 222 7 152 600
26 B 223 9 142 667
49 S 224 3 190 594
50 S 225 1 167 576
59 C 212
10 S 227 0 101 404
4 S 228 3 185 211
10 B 229 8 187 543
22 B 230 7 117 975
13 S 231 1 168 477
40 C 152
52 S 233 9 119 743
24 B 234 7 111 774
4 C 228
19 C 149
29 C 204
16 B 238 8 160 927
56 S 239 6 143 632
61 S 240 9 122 793
17 B 241 3 193 36
1 S 242 2 124 88
40 C 117
31 C 153
46 S 245 1 152 716
24 B 246 6 141 735
31 B 247 3 114 133
40 C 117
2 S 249 7 172 852
58 S 250 3 141 108
14 B 251 0 108 950
58 S 252 5 116 631
39 B 253 2 135 403
63 B 254 5 109 485
25 S 255 3 170 237
20 S 256 0 159 119
57 S 257 6 192 788
36 C 145
1 C 210
49 C 136
28 B 261 5 119 16
35 S 262 3 195 733
40 B 263 1 116 376
46 C 245
26 S 265 9 162 38
42 S 266 0 144 619
48 B 267 1 165 181
59 S 268 9 136 482
11 B 269 5 154 395
7 B 270 5 183 103
59 C 268
62 B 272 8 156 674
11 S 273 6 161 10
49 B 274 2 106 954
20 S 275 3 158 496
58 B 276 4 160 930
55 B 277 7 153 837
0 B 278 7 178 498
56 C 239
29 C 204
13 B 281 7 133 547
38 S 282 7 196 997
12 C 160
17 B 284 5 112 817
14 C 203
28 B 286 6 111 791
37 S 287 6 163 494
52 B 288 5 149 218
14 S 289 7 197 646
1 C 210
19 B 291 1 151 513
9 B 292 7 191 200
38 B 293 7 162 558
40 C 263
34 B 295 1 132 978
29 B 296 6 190 358
2 B 297 4 143 908
8 S 298 8 148 816
9 C 292
12 C 160
55 B 301 7 119 259
32 C 106
34 S 303 4 103 357
2 S 304 2 117 318
2 B 305 7 192 217
59 B 306 8 124 59
46 B 307 8 184 999
25 B 308 7 150 253
46 S 309 5 162 491
10 S 310 9 156 331
9 B 311 9 147 985
16 S 312 8 153 111
59 C 218
40 S 314 7 126 15
55 S 315 4 139 992
59 C 306
43 C 102
46 C 309
35 S 319 5 159 363
24 S 320 6 179 960
49 S 321 4 188 599
60 B 322 6 168 867
61 B 323 5 107 957
55 S 324 6 188 978
35 S 325 1 170 122
3 C 126
30 B 327 7 186 114
46 C 307
2 B 329 8 126 701
22 C 159
31 C 247
51 B 332 5 165 17
58 B 333 1 136 690
46 S 334 8 185 543
10 S 335 2 163 426
11 S 336 9 107 439
15 S 337 1 109 588
52 B 338 6 200 148
36 B 339 7 181 600
32 C 106
55 S 341 6 198 713
19 B 342 2 196 559
40 B 343 6 131 341
54 S 344 6 195 397
60 B 345 6 164 598
18 S 346 6 163 403
11 B 347 3 133 815
58 B 348 8 143 175
26 C 265
25 C 308
42 B 351 3 132 314
18 S 352 6 199 527
36 C 145
63 C 167
45 B 355 7 105 12
29 B 356 2 168 18
12 C 160
38 S 358 3 161 664
57 B 359 0 172 818
2 B 360 4 145 350
10 C 310
42 B 363 1 100 623
4 B 364 2 187 812
10 B 365 6 200 141
20 B 366 9 102 300
40 B 367 4 121 74
7 B 368 4 148 659
62 B 369 9 174 590
5 B 370 0 187 915
12 B 371 8 188 235
52 B 372 3 104 648
31 C 247
2 B 374 5 161 397
57 C 257
58 C 252
40 C 367
53 S 378 6 186 857
57 S 379 2 131 384
44 S 380 8 196 302
22 C 159
57 S 382 0 111 428
6 S 383 5 161 32
61 C 323
43 B 385 8 156 489
2 S 386 9 182 261
19 S 387 9 129 648
6 S 388 8 153 609
59 S 389 7 123 288
55 C 324
30 S 391 2 178 103
1 C 210
14 B 393 4 194 22
41 B 394 8 112 876
53 S 395 5 117 933
58 B 396 9 180 40
56 B 397 4 199 579
3 C 126
28 S 399 5 101 646
41 B 400 6 159 11
60 S 401 8 172 64
0 B 402 7 176 976
25 B 403 0 176 226
52 C 372
36 B 405 0 188 459
41 C 222
46 S 407 9 131 992
2 B 408 2 144 793
7 C 190
4 C 364
39 S 411 0 125 787
28 C 399
31 C 221
19 B 414 7 181 947
44 S 415 4 124 834
37 B 416 6 180 20
44 C 415
21 S 418 5 108 67
3 B 419 6 123 798
58 S 420 1 100 616
35 S 421 3 149 903
32 B 422 9 187 72
10 S 423 7 100 14
46 B 424 3 156 106
60 C 322
32 B 426 6 177 415
37 S 427 9 151 51
58 B 428 3 116 574
56 S 429 7 138 415
40 S 430 8 133 448
0 B 431 9 158 634
12 B 432 6 160 964
29 C 204
61 B 434 7 117 810
45 B 435 4 155 904
63 B 436 7 101 459
59 S 437 6 183 625
53 B 438 8 138 591
22 C 230
8 S 440 7 152 352
5 C 370
36 C 339
32 C 106
35 C 262
44 S 445 7 158 958
53 S 446 7 179 925
32 S 447 6 137 84
43 B 448 3 124 172
27 B 449 4 101 353
18 C 346
28 B 451 4 101 223
20 B 452 1 190 356
31 S 453 6 154 726
8 C 175
40 B 455 6 167 153
35 S 457 1 101 909
14 C 393
27 B 459 7 131 243
6 B 460 3 101 249
61 B 461 1 122 459
48 B 462 8 195 458
56 S 463 9 180 187
0 C 431
34 C 303
54 B 466 8 118 296
23 C 148
18 C 162
20 B 469 9 181 791
22 C 205
40 C 343
9 B 472 8 120 955
9 S 473 9 193 202
7 S 474 3 185 367
31 S 475 7 136 295
23 C 148
13 C 281
8 B 478 3 186 300
0 S 479 8 169 791
8 B 480 9 129 257
63 C 436
15 C 201
39 B 483 1 193 555
19 S 484 0 133 720
15 B 485 4 115 132
33 S 486 7 102 871
42 C 363
19 B 488 8 157 96
34 B 489 4 171 277
4 C 228
35 C 421
10 B 492 9 103 817
52 S 493 0 194 623
19 B 494 1 189 941
13 B 495 4 199 378
2 S 496 0 134 260
18 S 497 4 104 818
29 B 498 8 189 345
6 C 383
36 B 500 0 167 203
63 S 501 4 170 304
22 B 502 1 119 716
41 C 222
8 C 298
10 S 505 1 177 881
4 C 228
39 B 507 6 111 930
32 S 508 3 195 667
50 S 509 4 175 373
19 B 510 1 143 795
2 C 360
61 B 512 9 180 224
52 C 101
30 C 327
24 B 515 2 139 585
60 S 516 3 123 47
24 S 517 7 165 845
8 S 518 8 121 480
30 S 519 5 143 754
35 C 421
39 S 521 1 135 406
17 S 522 7 164 837
49 S 523 4 191 697
39 S 524 7 195 829
6 B 525 9 135 20
14 B 526 8 185 519
10 B 527 6 114 741
14 S 528 0 151 449
15 C 201
10 S 530 9 135 490
22 S 531 2 133 388
47 S 532 9 147 165
9 C 292
23 B 534 0 195 786
26 B 535 5 127 601
13 S 536 5 129 616
51 B 537 4 112 702
42 S 538 7 135 105
6 C 525
44 C 114
7 B 541 3 150 731
2 B 542 9 122 761
9 B 543 2 118 385
54 C 170
56 B 545 2 143 394
7 B 546 8 141 583
7 C 541
53 B 548 6 136 401
20 C 200
10 C 492
62 S 551 6 166 635
32 C 447
43 B 553 5 154 523
37 C 287
62 C 184
59 S 556 5 176 251
53 S 557 9 193 679
55 S 558 5 195 663
11 S 559 0 105 160
8 S 560 9 132 759
45 S 561 5 195 361
31 B 562 9 109 338
45 S 563 1 125 424
45 C 563
16 B 565 3 161 689
25 B 566 6 118 220
23 S 567 0 193 515
4 C 228
39 C 507
1 B 570 7 164 571
63 S 571 1 172 34
43 S 572 3 192 613
31 C 562
40 S 574 6 163 55
34 C 183
13 B 576 7 162 120
54 B 577 3 146 988
22 C 230
21 B 579 9 190 102
45 B 580 2 161 230
31 C 475
41 S 582 8 133 251
58 S 583 8 194 674
58 B 584 0 117 277
10 B 585 8 193 582
22 S 586 4 169 970
28 C 451
7 B 588 7 121 189
58 S 589 8 113 680
0 C 479
47 C 532
44 S 592 8 168 477
38 C 293
60 B 594 1 134 432
15 S 595 3 181 943
44 B 596 5 195 683
15 B 597 6 192 76
24 B 598 4 141 108
34 S 599 0 180 930
0 C 278
8 B 601 0 127 550
7 C 270
17 S 603 1 105 965
5 S 604 7 178 692
52 C 493
17 C 284
49 S 607 3 111 676
11 B 608 2 138 689
55 S 609 6 143 967
51 S 610 3 144 907
5 S 611 0 170 705
16 B 612 2 124 545
6 B 613 1 192 168
13 S 614 2 146 288
57 C 116
59 C 268
62 B 617 3 188 957
6 B 618 7 116 477
42 S 619 4 148 657
44 B 620 7 128 886
